Workbook

Sheet Препод
A1: № пары | B1: ='На неделю'!A2 -> 144 | C1: ='На неделю'!B2 -> 145 | D1: ='На неделю'!C2 -> 146 | E1: ='На неделю'!D2 -> 147 | F1: ='На неделю'!E2 -> 148 | G1: ='На неделю'!F2 -> 149 | H1: ='На неделю'!G2 -> 150 | I1: ='На неделю'!H2 -> 151 | ... Q1: ='На неделю'!P2 -> 159 | R1: ='На неделю'!R2 -> 161 | S1: ='На неделю'!S2 -> 0 | T1: ='На неделю'!T2 -> РАСПИСАНИЕ ЗВОНКОВ | U1: ='На неделю'!U2 -> 0 | V1: ='На неделю'!A2 -> 144 | W1: ='На неделю'!B2 -> 145 | X1: ='На неделю'!C2 -> 146 | Y1: ='На неделю'!D2 -> 147 | Z1: ='На неделю'!E2 -> 148 | AA1: ='На неделю'!F2 -> 149 | AB1: ='На неделю'!G2 -> 150 | AC1: ='На неделю'!H2 -> 151 | ... AK1: ='На неделю'!P2 -> 159 | AL1: ='На неделю'!R2 -> 161 | AM1: ='На неделю'!S2 -> 0 | AN1: ='На неделю'!T2 -> РАСПИСАНИЕ ЗВОНКОВ | AO1: ='На неделю'!U2 -> 0
A2: Понедельник | V2: Вторник
A3: 1 | B3: ='На неделю'!A6 -> 0 | C3: ='На неделю'!B6 -> 0 | D3: ='На неделю'!C6 -> 0 | E3: ='На неделю'!D6 -> 0 | F3: ='На неделю'!E6 -> 0 | G3: ='На неделю'!F6 -> 0 | H3: ='На неделю'!G6 -> 0 | I3: ='На неделю'!H6 -> 0 | ... Q3: ='На неделю'!P6 -> 0 | R3: ='На неделю'!R6 -> 0 | S3: ='На неделю'!S6 -> 0 | T3: ='На неделю'!T6 -> 9.55 - 10.40 2 урок | U3: ='На неделю'!U6 -> 0 | V3: ='На неделю'!A18 -> Курат. Час (библ.) | W3: ='На неделю'!B18 -> Курат. Час 44. | X3: ='На неделю'!C18 -> Курат. Час 53 | Y3: ='На неделю'!D18 -> Курат. Час 22 | Z3: ='На неделю'!#REF! -> #REF! | AA3: ='На неделю'!#REF! -> #REF! | AB3: ='На неделю'!G18 -> Курат. Час 54 | AC3: ='На неделю'!H18 -> Курат. Час 21 | AD3: ='На неделю'!I18 -> Курат. Час 35 | AE3: ='На неделю'!J18 -> Курат. Час 13 | AF3: ='На неделю'!K18 -> Курат. Час 45 | AG3: ='На неделю'!L18 -> Курат. Час 12 | AH3: ='На неделю'!M18 -> Курат. Час 33 | AI3: ='На неделю'!N18 -> (25) Курат. Час | ... AK3: ='На неделю'!P18 -> Курат. Час 41 | AL3: ='На неделю'!R18 -> Курат. Час 24 | AM3: ='На неделю'!S18 -> 0 | AN3: ='На неделю'!T18 -> 9.55 - 10.40 2 урок | AO3: ='На неделю'!U18 -> 0
A4: 2 | B4: ='На неделю'!A8 -> 0 | C4: ='На неделю'!B8 -> 0 | D4: ='На неделю'!C8 -> 0 | E4: ='На неделю'!D8 -> 0 | F4: ='На неделю'!E8 -> 0 | G4: ='На неделю'!F8 -> 0 | H4: ='На неделю'!G8 -> 0 | I4: ='На неделю'!H7 -> 0 | J4: ='На неделю'!I8 -> 0 | K4: ='На неделю'!J8 -> 0 | L4: ='На неделю'!K8 -> 0 | M4: ='На неделю'!L8 -> 0 | N4: ='На неделю'!M8 -> 0 | O4: ='На неделю'!N8 -> 0 | P4: ='На неделю'!O8 -> 0 | Q4: ='На неделю'!P8 -> 0 | R4: ='На неделю'!R8 -> 0 | S4: ='На неделю'!S8 -> 0 | T4: ='На неделю'!T8 -> 11.45 - 12.30 4 урок | U4: ='На неделю'!U8 -> 0 | V4: ='На неделю'!A20 -> Гордиевич Е.И. | W4: ='На неделю'!B20 -> Каминский Н.В. | X4: ='На неделю'!C22 -> Козенков | Y4: ='На неделю'!D20 -> Концевая Т.В. | Z4: ='На неделю'!E21 -> П/О | AA4: ='На неделю'!F20 -> 0 | AB4: ='На неделю'!G20 -> Якшина О.А. | AC4: ='На неделю'!H20 -> Цыбульская Е.А. | AD4: ='На неделю'!I20 -> Черненкова И.А. | AE4: ='На неделю'!J20 -> Ероха Е.В. | AF4: ='На неделю'!#REF! -> #REF! | AG4: ='На неделю'!L20 -> Осипова Н.А. | AH4: ='На неделю'!M20 -> Артеменко А.А. | AI4: ='На неделю'!N20 -> Смирнов А.Н. | AJ4: ='На неделю'!O20 -> Исакова Н.К. | AK4: ='На неделю'!P20 -> Гончарова Ю.А. | AL4: ='На неделю'!R20 -> Буевич С.В. | AM4: ='На неделю'!S20 -> 0 | AN4: ='На неделю'!T20 -> 11.45 - 12.30 4 урок | AO4: ='На неделю'!U20 -> 0
A5: 3 | B5: ='На неделю'!A10 -> 0 | C5: ='На неделю'!B10 -> 0 | D5: ='На неделю'!C10 -> 0 | E5: ='На неделю'!D10 -> 0 | F5: ='На неделю'!E10 -> 0 | G5: ='На неделю'!F10 -> 0 | H5: ='На неделю'!G10 -> 0 | I5: ='На неделю'!H10 -> 0 | ... Q5: ='На неделю'!P10 -> 0 | R5: ='На неделю'!R10 -> 0 | S5: ='На неделю'!S10 -> 0 | T5: ='На неделю'!T10 -> 13.55 - 14.40 6 урок | U5: ='На неделю'!U10 -> 0 | V5: ='На неделю'!A22 -> Каминский Н.В. | W5: ='На неделю'!B22 -> Шумило Д.М. | X5: ='На неделю'!#REF! -> #REF! | Y5: ='На неделю'!D22 -> Чекан Н.Н. | Z5: ='На неделю'!E22 -> 0 | AA5: ='На неделю'!F18 -> Курат. Час 51 | AB5: ='На неделю'!G22 -> Физическая культ. (Ч) | AC5: ='На неделю'!H22 -> Гордиевич Е.И. | AD5: ='На неделю'!I22 -> Пр.черчение 12 | AE5: ='На неделю'!J22 -> Сушинская Н.В. | AF5: ='На неделю'!K22 -> Якшина О.А. | AG5: ='На неделю'!L22 -> Федорцова А.Т. | AH5: ='На неделю'!M22 -> Смирнов А.Н. | AI5: ='На неделю'!N22 -> Артеменко А.А. | AJ5: ='На неделю'!#REF! -> #REF! | AK5: ='На неделю'!P22 -> Исакова Н.К. | AL5: ='На неделю'!R22 -> Сем. Я.А./Степ. И.В. | AM5: ='На неделю'!S22 -> 0 | AN5: ='На неделю'!T22 -> 13.55 - 14.40 6 урок | AO5: ='На неделю'!U22 -> 0
A6: 4 | B6: ='На неделю'!A11 -> 0 | C6: ='На неделю'!B12 -> 0 | D6: ='На неделю'!C12 -> 0 | E6: ='На неделю'!D12 -> 0 | F6: ='На неделю'!E12 -> 0 | G6: ='На неделю'!F12 -> 0 | H6: ='На неделю'!G12 -> 0 | I6: ='На неделю'!H12 -> 0 | J6: ='На неделю'!I12 -> 0 | ... Q6: ='На неделю'!P12 -> 0 | R6: ='На неделю'!R12 -> 0 | S6: ='На неделю'!S12 -> 0 | T6: ='На неделю'!T12 -> 15.45 - 16.30 8 урок | U6: ='На неделю'!U12 -> 0 | V6: ='На неделю'!A24 -> 0 | W6: ='На неделю'!B24 -> Шумило Д.М. | X6: ='На неделю'!C24 -> Гордиевич Е.И. | Y6: ='На неделю'!D24 -> 0 | Z6: ='На неделю'!#REF! -> #REF! | AA6: ='На неделю'!F24 -> 0 | AB6: ='На неделю'!G24 -> 0 | AC6: ='На неделю'!H24 -> 0 | AD6: ='На неделю'!I24 -> 0 | AE6: ='На неделю'!J24 -> 0 | AF6: ='На неделю'!K24 -> 0 | AG6: ='На неделю'!L24 -> 0 | AH6: ='На неделю'!M24 -> 0 | AI6: ='На неделю'!O22 -> Гончарова Ю.А. | AJ6: ='На неделю'!O24 -> 0 | AK6: ='На неделю'!P24 -> 0 | AL6: ='На неделю'!R24 -> 0 | AM6: ='На неделю'!S24 -> 0 | AN6: ='На неделю'!T24 -> 15.45 - 16.30 8 урок | AO6: ='На неделю'!U24 -> 0
A7: Среда | V7: Четверг
A8: 1 | B8: ='На неделю'!A30 -> Ануфриева/Степанова | C8: ='На неделю'!B30 -> 0 | D8: ='На неделю'!C30 -> 0 | E8: ='На неделю'!D30 -> Голубева Н.И. | F8: ='На неделю'!E30 -> 0 | G8: ='На неделю'!F30 -> Цыбульская Е.А. | H8: ='На неделю'!#REF! -> #REF! | I8: ='На неделю'!H30 -> Гордиевич Е.И. | J8: ='На неделю'!I30 -> Бел.язык 35(14) | K8: ='На неделю'!J30 -> Физ. культура (Ст/Ч) | L8: ='На неделю'!K30 -> Гончарова Ю.А. | M8: ='На неделю'!L30 -> Буевич С.В. | N8: ='На неделю'!M30 -> Федорцова А.Т. | O8: ='На неделю'!N30 -> Сушинская Н.В. | P8: ='На неделю'!O30 -> Страх В.М. | Q8: ='На неделю'!P30 -> Гаврилкина Л.П. | R8: ='На неделю'!R30 -> Якшина О.А. | S8: ='На неделю'!S30 -> 0 | T8: ='На неделю'!T30 -> 9.55 - 10.40 2 урок | U8: ='На неделю'!U30 -> 0 | V8: ='На неделю'!A42 -> Ануфриева/Семенова | W8: ='На неделю'!B42 -> 0 | X8: ='На неделю'!C42 -> 0 | Y8: ='На неделю'!D42 -> Чекан Н.Н. | Z8: ='На неделю'!E42 -> 0 | AA8: ='На неделю'!F42 -> Каминский Н.В. | AB8: ='На неделю'!G42 -> Шумило Д.М. | AC8: ='На неделю'!H42 -> Гордиевич Е.И. | ... AK8: ='На неделю'!P42 -> Цыбульская Е.А. | AL8: ='На неделю'!R42 -> Гаврилкина Л.П. | AM8: ='На неделю'!S42 -> 0 | AN8: ='На неделю'!T42 -> 9.55 - 10.40 2 урок | AO8: ='На неделю'!U42 -> 0
A9: 2 | B9: ='На неделю'!A32 -> Каминский Н.В. | C9: ='На неделю'!B32 -> ПП | D9: ='На неделю'!C32 -> ПО | E9: ='На неделю'!D32 -> Голубева Н.И. | F9: ='На неделю'!E32 -> П/О | G9: ='На неделю'!F32 -> Шумило Д.М. | H9: ='На неделю'!G32 -> Гордиевич Е.И. | I9: ='На неделю'!H32 -> Цыбульская Е.А. | J9: ='На неделю'!G30 -> Шумило Д.М. | K9: ='На неделю'!J32 -> Сушинская Н.В. | L9: ='На неделю'!K32 -> Рус.язык 34 (13) | M9: ='На неделю'!L32 -> Якшина О.А. | N9: ='На неделю'!M32 -> Гончарова Ю.А. | O9: ='На неделю'!N32 -> Артеменко А.А. | P9: ='На неделю'!O32 -> Физ. культура (Ст/Ч) | Q9: ='На неделю'!P32 -> Черненкова И.А. | R9: ='На неделю'!R32 -> География 32 (11) | S9: ='На неделю'!S32 -> 0 | T9: ='На неделю'!T32 -> 11.45 - 12.30 4 урок | U9: ='На неделю'!U32 -> 0 | V9: ='На неделю'!A44 -> Каминский Н.В. | W9: ='На неделю'!B44 -> ПП | X9: ='На неделю'!C44 -> ПО | Y9: ='На неделю'!D44 -> Чекан Н.Н. | Z9: ='На неделю'!E44 -> П/О | AA9: ='На неделю'!F44 -> Гордиевич Е.И. | AB9: ='На неделю'!G44 -> Цыбульская Е.А. | AC9: ='На неделю'!H44 -> Шумило Д.М. | ... AK9: ='На неделю'!P44 -> Гончарова Ю.А. | AL9: ='На неделю'!R44 -> Якшина О.А. | AM9: ='На неделю'!S44 -> 0 | AN9: ='На неделю'!T44 -> 11.45 - 12.30 4 урок | AO9: ='На неделю'!U44 -> 0
A10: 3 | B10: ='На неделю'!A34 -> Каминский Н.В. | C10: ='На неделю'!B34 -> 0 | D10: ='На неделю'!C34 -> 0 | E10: ='На неделю'!D34 -> Чекан Н.Н. | F10: ='На неделю'!E34 -> Осипова Н.А. | G10: ='На неделю'!F34 -> Гордиевич Е.И. | H10: ='На неделю'!G34 -> Артеменко А.А. | I10: ='На неделю'!H34 -> Шумило Д.М. | ... Q10: ='На неделю'!P34 -> История Беларуси 21(5) | R10: ='На неделю'!R34 -> Физ. культура (Ст/Ч) | S10: ='На неделю'!S34 -> 0 | T10: ='На неделю'!T34 -> 13.55 - 14.40 6 урок | U10: ='На неделю'!U34 -> 0 | V10: ='На неделю'!A46 -> Ануфриева/Степанова | W10: ='На неделю'!B46 -> 0 | X10: ='На неделю'!C46 -> 0 | Y10: ='На неделю'!D46 -> Голубева Н.И. | Z10: ='На неделю'!E46 -> "Учебный | AA10: ='На неделю'!F46 -> Шумило Д.М. | AB10: ='На неделю'!G46 -> Гордиевич Е.И. | AC10: ='На неделю'!H46 -> Физическая культура (Ч) | ... AK10: ='На неделю'!P46 -> Федорцова А.Т. | AL10: ='На неделю'!R46 -> Цыбульская Е.А. | AM10: ='На неделю'!S46 -> 0 | AN10: ='На неделю'!T46 -> 13.55 - 14.40 6 урок | AO10: ='На неделю'!U46 -> 0
A11: 4 | B11: ='На неделю'!A36 -> Ануфриева/Семенова | C11: ='На неделю'!B36 -> 0 | D11: ='На неделю'!C36 -> 0 | E11: ='На неделю'!D36 -> Чекан Н.Н. | F11: ='На неделю'!E36 -> 0 | G11: ='На неделю'!F36 -> -------------------------------- | H11: ='На неделю'!G36 -> -------------------------------- | I11: ='На неделю'!H36 -> -------------------------------- | ... Q11: ='На неделю'!P36 -> -------------------------------- | R11: ='На неделю'!R36 -> -------------------------------- | S11: ='На неделю'!S36 -> 0 | T11: ='На неделю'!T36 -> 15.45 - 16.30 8 урок | U11: ='На неделю'!U36 -> 0 | V11: ='На неделю'!A48 -> Гордиевич Е.И. | W11: ='На неделю'!B48 -> 0 | X11: ='На неделю'!C48 -> 0 | Y11: ='На неделю'!D48 -> Голубева Н.И. | Z11: ='На неделю'!E48 -> 0 | AA11: ='На неделю'!F48 -> Физическая культура (Ч) | AB11: ='На неделю'!G48 -> -------------------------------- | AC11: ='На неделю'!H48 -> Сушинская Н.В. | ... AK11: ='На неделю'!P48 -> Страх В.М. | AL11: ='На неделю'!R48 -> Исакова Н.К. | AM11: ='На неделю'!S48 -> 0 | AN11: ='На неделю'!T48 -> 15.45 - 16.30 8 урок | AO11: ='На неделю'!U48 -> 0
A12: Пятница
A13: 1 | B13: ='На неделю'!A54 -> Каминский Н.В. | C13: ='На неделю'!B54 -> 0 | D13: ='На неделю'!C54 -> 0 | E13: ='На неделю'!D54 -> Чекан Н.Н. | F13: ='На неделю'!E54 -> 0 | G13: ='На неделю'!F54 -> Гордиевич Е.И. | H13: ='На неделю'!G54 -> Артеменко А.А. | I13: ='На неделю'!H54 -> Якшина О.А. | J13: ='На неделю'!I54 -> Ануфриева/Степанова | K13: ='На неделю'!#REF! -> #REF! | L13: ='На неделю'!K54 -> Бел.литература 35(14) | M13: ='На неделю'!L54 -> Буевич С.В. | N13: ='На неделю'!M54 -> Федорцова А.Т. | O13: ='На неделю'!N54 -> Цыбульская Е.А. | P13: ='На неделю'!O54 -> Физ. культура (Ст/Ч) | Q13: ='На неделю'!P54 -> Гаврилкина Л.П. | R13: ='На неделю'!R54 -> Осипова Н.А. | S13: ='На неделю'!S54 -> 0 | T13: ='На неделю'!T54 -> 9.55 - 10.40 2 урок | U13: ='На неделю'!U54 -> 0
A14: 2 | B14: ='На неделю'!A56 -> Каминский Н.В. | C14: ='На неделю'!B56 -> ПП | D14: ='На неделю'!C56 -> ПО | E14: ='На неделю'!D56 -> Чекан Н.Н. | F14: ='На неделю'!E56 -> П/О | G14: ='На неделю'!F56 -> Якшина О.А. | H14: ='На неделю'!G56 -> Гордиевич Е.И. | I14: ='На неделю'!H56 -> Артеменко А.А. | ... Q14: ='На неделю'!P56 -> Буевич С.В. | R14: ='На неделю'!R56 -> Федорцова А.Т. | S14: ='На неделю'!S56 -> 0 | T14: ='На неделю'!T56 -> 11.45 - 12.30 4 урок | U14: ='На неделю'!U56 -> 0
A15: 3 | B15: ='На неделю'!A58 -> Каминский Н.В. | C15: ='На неделю'!B58 -> 0 | D15: ='На неделю'!C58 -> 0 | E15: ='На неделю'!D58 -> Чевидаев/Столбицкий | F15: ='На неделю'!E58 -> "Учебный | G15: ='На неделю'!F58 -> Артеменко А.А. | H15: ='На неделю'!G58 -> Якшина О.А. | I15: ='На неделю'!H58 -> Гордиевич Е.И. | ... Q15: ='На неделю'!P58 -> Страх В.М. | R15: ='На неделю'!R58 -> Черненкова И.А. | S15: ='На неделю'!S58 -> 0 | T15: ='На неделю'!T58 -> 13.55 - 14.40 6 урок | U15: ='На неделю'!U58 -> 0
A16: 4 | B16: ='На неделю'!A60 -> -------------------------------- | C16: ='На неделю'!B60 -> 0 | D16: ='На неделю'!C60 -> 0 | E16: ='На неделю'!D60 -> -------------------------------- | F16: ='На неделю'!E60 -> 0 | G16: ='На неделю'!F60 -> -------------------------------- | H16: ='На неделю'!G60 -> -------------------------------- | I16: ='На неделю'!H60 -> -------------------------------- | ... Q16: ='На неделю'!P60 -> -------------------------------- | R16: ='На неделю'!R60 -> -------------------------------- | S16: ='На неделю'!S60 -> -------------------------------- | T16: ='На неделю'!T60 -> 15.45 - 16.30 8 урок | U16: ='На неделю'!U60 -> 0

Sheet Бланк
A1: ='На неделю'!A1:E1 -> Расписание занятий с
A3: ='На неделю'!A2 -> 144 | B3: ='На неделю'!B2 -> 145 | C3: ='На неделю'!C2 -> 146 | D3: ='На неделю'!D2 -> 147 | E3: ='На неделю'!E2 -> 148 | F3: ='На неделю'!F2 -> 149 | G3: ='На неделю'!G2 -> 150 | H3: ='На неделю'!H2 -> 151 | ... P3: ='На неделю'!P2 -> 159 | Q3: ='На неделю'!R2 -> 161 | R3: ='На неделю'!S2 -> 0 | S3: ='На неделю'!T2 -> РАСПИСАНИЕ ЗВОНКОВ | T3: ='На неделю'!U2 -> 0
A4: Понедельник
A11: Вторник
A18: Среда
A25: Четверг
A32: Пятница

Sheet На неделю
A1: Расписание занятий с | D1: 46266 | E1: по 04.09.2026 | F1: =A1 -> Расписание занятий с | I1: =D1 -> 46266 | J1: =E1 -> по 04.09.2026 | K1: =F1 -> Расписание занятий с | N1: =I1 -> 46266 | P1: =K1 -> Расписание занятий с | T1: =N1 -> 46266 | U1: =O1 -> 0
A2: 144 | B2: 145 | C2: 146 | D2: 147 | E2: 148 | F2: 149 | G2: 150 | H2: 151 | I2: 152 | J2: 153 | K2: 154 | L2: 155 | M2: 156 | N2: 157 | O2: 158 | P2: 159 | Q2: 160 | R2: 161 | T2: РАСПИСАНИЕ ЗВОНКОВ | V2: =A2 -> 144 | W2: =B2 -> 145 | X2: =C2 -> 146 | Y2: =D2 -> 147 | Z2: =E2 -> 148 | AA2: =F2 -> 149 | AB2: =G2 -> 150 | AC2: =H2 -> 151 | ... AM2: =R2 -> 161
A3: Понедельник | F3: Понедельник | K3: Понедельник | P3: Понедельник
T4: 8.05 - 8.50 0 урок | V4: =RIGHT(A4,2) | W4: =RIGHT(B4,2) | X4: =RIGHT(C4,2) | Y4: =RIGHT(D4,2) | Z4: =RIGHT(E4,2) | AA4: =RIGHT(F4,2) | AB4: =RIGHT(G4,2) | AC4: =RIGHT(H4,2) | ... AM4: =RIGHT(R4,2)
T5: 9.00 - 9.45 1 урок | V5: =RIGHT(A5,2) | W5: =RIGHT(B5,2) | X5: =RIGHT(C5,2) | Y5: =RIGHT(D5,2) | Z5: =RIGHT(E5,2) | AA5: =RIGHT(F5,2) | AB5: =RIGHT(G5,2) | AC5: =RIGHT(H5,2) | ... AM5: =RIGHT(R5,2)
T6: 9.55 - 10.40 2 урок
T7: 10.50 - 11.35 3 урок | V7: =RIGHT(A7,2) | W7: =RIGHT(B7,2) | X7: =RIGHT(C7,2) | Y7: =RIGHT(D7,2) | Z7: =RIGHT(E7,2) | AA7: =RIGHT(F7,2) | AB7: =RIGHT(G7,2) | AC7: =RIGHT(#REF!,2) -> #REF! | AD7: =RIGHT(I7,2) | AE7: =RIGHT(J7,2) | AF7: =RIGHT(K7,2) | AG7: =RIGHT(L7,2) | AH7: =RIGHT(M7,2) | AI7: =RIGHT(N7,2) | AJ7: =RIGHT(O7,2) | AK7: =RIGHT(P7,2) | ... AM7: =RIGHT(R7,2)
T8: 11.45 - 12.30 4 урок
T9: 12.50 - 13.35 5 урок | V9: =RIGHT(A9,2) | W9: =RIGHT(B9,2) | X9: =RIGHT(C9,2) | Y9: =RIGHT(D9,2) | Z9: =RIGHT(E9,2) | AA9: =RIGHT(F9,2) | AB9: =RIGHT(G9,2) | AC9: =RIGHT(H9,2) | ... AM9: =RIGHT(R9,2)
T10: 13.55 - 14.40 6 урок
T11: 14.50 - 15.35 7 урок | V11: =RIGHT(#REF!,2) -> #REF! | W11: =RIGHT(B11,2) | X11: =RIGHT(C11,2) | Y11: =RIGHT(D11,2) | Z11: =RIGHT(E11,2) | AA11: =RIGHT(F11,2) | AB11: =RIGHT(G11,2) | AC11: =RIGHT(H11,2) | AD11: =RIGHT(I11,2) | ... AM11: =RIGHT(R11,2)
T12: 15.45 - 16.30 8 урок
V13: =RIGHT(A12,2) | W13: =RIGHT(B13,2) | X13: =RIGHT(C13,2) | Y13: =RIGHT(D13,2) | Z13: =RIGHT(E13,2) | AA13: =RIGHT(F13,2) | AB13: =RIGHT(G13,2) | AC13: =RIGHT(H13,2) | AD13: =RIGHT(I13,2) | ... AM13: =RIGHT(R13,2)
A15: Вторник | F15: Вторник | K15: Вторник | P15: Вторник
T16: 8.05 - 8.50 0 урок | V16: =RIGHT(A16,2) | W16: =RIGHT(B16,2) | X16: =RIGHT(C16,2) | Y16: =RIGHT(D16,2) | Z16: =RIGHT(E16,2) | AA16: =RIGHT(F16,2) | AB16: =RIGHT(G16,2) | AC16: =RIGHT(H16,2) | ... AM16: =RIGHT(R16,2)
A17: Линейка | B17: Линейка | C17: Линейка | D17: Линейка | E17: Линейка | F17: Линейка | G17: Линейка | H17: Линейка | I17: Линейка | J17: Линейка | K17: Линейка | L17: Линейка | M17: Линейка | N17: Линейка | O17: Линейка | P17: Линейка | Q17: Линейка | R17: Линейка | T17: 9.00 - 9.45 1 урок | V17: =RIGHT(A17,2) -> ка | W17: =RIGHT(B17,2) -> ка | X17: =RIGHT(C17,2) -> ка | Y17: =RIGHT(D17,2) -> ка | Z17: =RIGHT(E17,2) -> ка | AA17: =RIGHT(F17,2) -> ка | AB17: =RIGHT(G17,2) -> ка | AC17: =RIGHT(H17,2) -> ка | ... AM17: =RIGHT(R17,2) -> ка
A18: Курат. Час (библ.) | B18: Курат. Час 44. | C18: Курат. Час 53 | D18: Курат. Час 22 | E18: Курат. Час 34 | F18: Курат. Час 51 | G18: Курат. Час 54 | H18: Курат. Час 21 | I18: Курат. Час 35 | J18: Курат. Час 13 | K18: Курат. Час 45 | L18: Курат. Час 12 | M18: Курат. Час 33 | N18: (25) Курат. Час | O18: Курат. Час 31 | P18: Курат. Час 41 | Q18: Курат. Час 14 | R18: Курат. Час 24 | T18: 9.55 - 10.40 2 урок
A19: ТО и Р ТС 53 | B19: Устройство авто 54 | C19: Маш. и обор. живот. 51 | D19: Калькул. и уч 14 | G19: Обществоведение 33 | H19: Пр.черчение 12 | I19: Бел.литература 35 | J19: Рисоване и лепка 11 | K19: История Беларуси 21 | L19: Торг. оборудование 24 | M19: Математика 41 | N19: Допр. Подготовка 25 | O19: Русск. Лит 34 | P19: Математика 45 | Q19: Химия44 | R19: Биология 32 | T19: 10.50 - 11.35 3 урок | V19: =RIGHT(A19,2) -> 53 | W19: =RIGHT(B19,2) -> 54 | X19: =RIGHT(C21,2) -> ьт | Y19: =RIGHT(D19,2) -> 14 | Z19: =RIGHT(E19,2) | AA19: =RIGHT(F19,2) | AB19: =RIGHT(G19,2) -> 33 | AC19: =RIGHT(H19,2) -> 12 | AD19: =RIGHT(I19,2) -> 35 | AE19: =RIGHT(J19,2) -> 11 | AF19: =RIGHT(K19,2) -> 21 | ... AM19: =RIGHT(R19,2) -> 2
A20: Гордиевич Е.И. | B20: Каминский Н.В. | C20: Шумило Д.М. | D20: Концевая Т.В. | G20: Якшина О.А. | H20: Цыбульская Е.А. | I20: Черненкова И.А. | J20: Ероха Е.В. | K20: Сушинская Н.В. | L20: Осипова Н.А. | M20: Артеменко А.А. | N20: Смирнов А.Н. | O20: Исакова Н.К. | P20: Гончарова Ю.А. | Q20: Федорцова А.Т. | R20: Буевич С.В. | T20: 11.45 - 12.30 4 урок
A21: Устройство авто 54 | B21: Маш. и обор. живот. 51 | C21: Физическая культ | D21: Спецтехнология (К) 23 | E21: П/О | F21: П/О | G21: Охрана труда 12(Ц) | H21: Устр-во тракторов 53 | I21: Физическая культ. (Зен.) | J21: История Беларуси 21 | K21: Обществоведение 33 | L21: Химия 44 | M21: Допр. Подготовка 25 | N21: Физика 41 | O21: Математика 45 | P21: Русск. Лит 34 | Q21: Спецтехнология (П) 22 | R21: Ин. Яз. 13/43 | T21: 12.50 - 13.35 5 урок | V21: =RIGHT(A21,2) -> 54 | W21: =RIGHT(B21,2) -> 51 | X21: =RIGHT(#REF!,2) -> #REF! | Y21: =RIGHT(D21,2) -> 23 | Z21: =RIGHT(#REF!,2) -> #REF! | AA21: =RIGHT(F21,2) -> /О | AB21: =RIGHT(G21,2) -> Ц) | AC21: =RIGHT(H21,2) -> 3 | AD21: =RIGHT(I21,2) -> .) | AE21: =RIGHT(J21,2) -> 21 | AF21: =RIGHT(K21,2) -> 33 | AG21: =RIGHT(L21,2) -> 4 | AH21: =RIGHT(M21,2) -> 25 | AI21: =RIGHT(N21,2) -> 41 | AJ21: =RIGHT(#REF!,2) -> #REF! | AK21: =RIGHT(P21,2) -> 34 | AL21: =RIGHT(Q21,2) -> 22 | AM21: =RIGHT(R21,2) -> 43
A22: Каминский Н.В. | B22: Шумило Д.М. | C22: Козенков | D22: Чекан Н.Н. | G22: Физическая культ. (Ч) | H22: Гордиевич Е.И. | I22: Пр.черчение 12 | J22: Сушинская Н.В. | K22: Якшина О.А. | L22: Федорцова А.Т. | M22: Смирнов А.Н. | N22: Артеменко А.А. | O22: Гончарова Ю.А. | P22: Исакова Н.К. | Q22: Голубева Н.И. | R22: Сем. Я.А./Степ. И.В. | T22: 13.55 - 14.40 6 урок
B23: Устр. самоход. маш. 20 | C23: ТО и Р ТС 53 | O23: Физическая культ. (С) | T23: 14.50 - 15.35 7 урок | V23: =RIGHT(A23,2) | W23: =RIGHT(B23,2) -> 20 | X23: =RIGHT(C23,2) -> 53 | Y23: =RIGHT(D23,2) | Z23: =RIGHT(E23,2) | AA23: =RIGHT(F23,2) | AB23: =RIGHT(G23,2) | AC23: =RIGHT(H23,2) | ... AH23: =RIGHT(M23,2) | AI23: =RIGHT(O21,2) -> 45 | AJ23: =RIGHT(O23,2) -> С) | AK23: =RIGHT(P23,2) | AL23: =RIGHT(Q23,2) | AM23: =RIGHT(R23,2)
B24: Шумило Д.М. | C24: Гордиевич Е.И. | T24: 15.45 - 16.30 8 урок
V25: =RIGHT(A25,2) | W25: =RIGHT(B25,2) | X25: =RIGHT(C25,2) | Y25: =RIGHT(D25,2) | Z25: =RIGHT(E25,2) | AA25: =RIGHT(F25,2) | AB25: =RIGHT(G25,2) | AC25: =RIGHT(H25,2) | ... AM25: =RIGHT(R25,2)
A27: Среда | F27: Среда | K27: Среда | P27: Среда
T28: 8.05 - 8.50 0 урок | V28: =RIGHT(A28,2) | W28: =RIGHT(B28,2) | X28: =RIGHT(C28,2) | Y28: =RIGHT(D28,2) | Z28: =RIGHT(E28,2) | AA28: =RIGHT(F28,2) | AB28: =RIGHT(G28,2) | AC28: =RIGHT(H28,2) | ... AM28: =RIGHT(R28,2)
A29: Пр.инф.2/Ин.в пр.1 31/43 | D29: Спецтехнология (П) 22 | F29: Черчение 12 (2) | G29: Устр.агр.т.и обор.14(20) | H29: Устр-во тракторов 53 (21) | I29: Физ. культура (Ст/Ч) | J29: Бел.язык 35(14) | K29: Математика 45 (19) | L29: Биология 32 (11) | M29: Химия 44 (18) | N29: История Беларуси 21(5) | O29: ЗНТЧС 25(9) | P29: Физика 11 (1) | Q29: Обществоведение 33(12) | R29: Обществоведение 33(12) | T29: 9.00 - 9.45 1 урок | V29: =RIGHT(A29,2) -> 43 | W29: =RIGHT(B29,2) | X29: =RIGHT(C29,2) | Y29: =RIGHT(D29,2) -> 22 | Z29: =RIGHT(E29,2) | AA29: =RIGHT(F29,2) -> 2) | AB29: =RIGHT(G29,2) -> 0) | AC29: =RIGHT(H29,2) -> 1) | ... AM29: =RIGHT(R29,2) -> 2)
A30: Ануфриева/Степанова | D30: Голубева Н.И. | F30: Цыбульская Е.А. | G30: Шумило Д.М. | H30: Гордиевич Е.И. | I30: Бел.язык 35(14) | J30: Физ. культура (Ст/Ч) | K30: Гончарова Ю.А. | L30: Буевич С.В. | M30: Федорцова А.Т. | N30: Сушинская Н.В. | O30: Страх В.М. | P30: Гаврилкина Л.П. | Q30: Якшина О.А. | R30: Якшина О.А. | T30: 9.55 - 10.40 2 урок
A31: Устройство авто 55(31) | D31: Спецтехнология (П) 22 | F31: Устр.агр.т.и обор.14(20) | G31: Устр-во тракторов 53 (21) | H31: Черчение 12 (2) | I31: Пр.инф.2/Ин.в пр.1 31/43 | J31: История Беларуси 21(5) | K31: Физ. культура (Ст/Ч) | L31: Основы права 33(12) | M31: Математика 45 (19) | N31: Математика 41 (15) | O31: Рус.язык 34 (13) | P31: Бел.литература 35(14) | Q31: Физика 11 (1) | R31: Физика 11 (1) | T31: 10.50 - 11.35 3 урок | V31: =RIGHT(A31,2) -> 1) | W31: =RIGHT(B31,2) | X31: =RIGHT(C31,2) | Y31: =RIGHT(D31,2) -> 22 | Z31: =RIGHT(E31,2) | AA31: =RIGHT(F31,2) -> 0) | AB31: =RIGHT(G31,2) -> 1) | AC31: =RIGHT(H31,2) -> 2) | ... AM31: =RIGHT(R31,2) -> 1)
A32: Каминский Н.В. | B32: ПП | C32: ПО | D32: Голубева Н.И. | E32: П/О | F32: Шумило Д.М. | G32: Гордиевич Е.И. | H32: Цыбульская Е.А. | I32: Ануфриева/Степанова | J32: Сушинская Н.В. | K32: Рус.язык 34 (13) | L32: Якшина О.А. | M32: Гончарова Ю.А. | N32: Артеменко А.А. | O32: Физ. культура (Ст/Ч) | P32: Черненкова И.А. | Q32: География 32 (11) | R32: География 32 (11) | T32: 11.45 - 12.30 4 урок
A33: ТО и Р авто 55(31) | D33: Спецтехнология (К) 23 | E33: Торг. вычисления 42 (16) | F33: Устр-во тракторов 53 (21) | G33: Математика 41 (15) | H33: Устр.агр.т.и обор.14(20) | I33: Пр.инф.1/Ин.в пр.2 31/13 | J33: Торг. вычисления 42 (16) | K33: Обществоведение 33(12) | L33: Бел.язык 35(14) | M33: Биология 32 (11) | N33: Химия 44 (18) | O33: Физика 11 (1) | P33: Физ. культура (Ст/Ч) | Q33: История Беларуси 21(5) | R33: История Беларуси 21(5) | T33: 12.50 - 13.35 5 урок | V33: =RIGHT(A33,2) -> 1) | W33: =RIGHT(B33,2) | X33: =RIGHT(C33,2) | Y33: =RIGHT(D33,2) -> 23 | Z33: =RIGHT(E33,2) -> 6) | AA33: =RIGHT(F33,2) -> 1) | AB33: =RIGHT(G33,2) -> 5) | AC33: =RIGHT(H33,2) -> 0) | ... AM33: =RIGHT(R33,2) -> 5)
A34: Каминский Н.В. | D34: Чекан Н.Н. | E34: Осипова Н.А. | F34: Гордиевич Е.И. | G34: Артеменко А.А. | H34: Шумило Д.М. | I34: Ануфриева/Семенова | J34: Осипова Н.А. | K34: Якшина О.А. | L34: Черненкова И.А. | M34: Буевич С.В. | N34: Федорцова А.Т. | O34: Гаврилкина Л.П. | P34: История Беларуси 21(5) | Q34: Физ. культура (Ст/Ч) | R34: Физ. культура (Ст/Ч) | T34: 13.55 - 14.40 6 урок
A35: Пр.инф.1/Ин.в пр.2 31/13 | D35: Спецтехнология (К) 23 | F35: -------------------------------- | G35: -------------------------------- | H35: -------------------------------- | I35: -------------------------------- | J35: -------------------------------- | K35: -------------------------------- | L35: -------------------------------- | M35: -------------------------------- | N35: -------------------------------- | O35: -------------------------------- | P35: -------------------------------- | Q35: -------------------------------- | R35: -------------------------------- | T35: 14.50 - 15.35 7 урок | V35: =RIGHT(A35,2) -> 13 | W35: =RIGHT(B35,2) | X35: =RIGHT(C35,2) | Y35: =RIGHT(D35,2) -> 23 | Z35: =RIGHT(E35,2) | AA35: =RIGHT(F35,2) -> -- | AB35: =RIGHT(G35,2) -> -- | AC35: =RIGHT(H35,2) -> -- | ... AM35: =RIGHT(R35,2) -> --
A36: Ануфриева/Семенова | D36: Чекан Н.Н. | F36: -------------------------------- | G36: -------------------------------- | H36: -------------------------------- | I36: -------------------------------- | J36: -------------------------------- | K36: -------------------------------- | L36: -------------------------------- | M36: -------------------------------- | N36: -------------------------------- | O36: -------------------------------- | P36: -------------------------------- | Q36: -------------------------------- | R36: -------------------------------- | T36: 15.45 - 16.30 8 урок
V37: =RIGHT(A37,2) | W37: =RIGHT(B37,2) | X37: =RIGHT(C37,2) | Y37: =RIGHT(D37,2) | Z37: =RIGHT(E37,2) | AA37: =RIGHT(F37,2) | AB37: =RIGHT(G37,2) | AC37: =RIGHT(H37,2) | ... AM37: =RIGHT(R37,2)
A39: Четверг | F39: Четверг | K39: Четверг | P39: Четверг
T40: 8.05 - 8.50 0 урок | V40: =RIGHT(A40,2) | W40: =RIGHT(B40,2) | X40: =RIGHT(C40,2) | Y40: =RIGHT(D40,2) | Z40: =RIGHT(E40,2) | AA40: =RIGHT(F40,2) | AB40: =RIGHT(G40,2) | AC40: =RIGHT(H40,2) | ... AM40: =RIGHT(R40,2)
A41: Пр.инф.1/Ин.в пр.2 31/13 | D41: Спецтехнология (К) 23 | F41: Устройство авто 55(31) | G41: Устр.агр.т.и обор.14(20) | H41: Устр-во тракторов 53 (21) | I41: Рус.литература 34 (13) | J41: География 32 (11) | K41: Астрономия 45 (19) | L41: Химия 44 (18) | M41: Бел.литература 35(14) | N41: Основы права 33(12) | O41: ЗНТЧС 25(9) | P41: Черчение 12(2) | Q41: Физика 11 (1) | R41: Физика 11 (1) | T41: 9.00 - 9.45 1 урок | V41: =RIGHT(A41,2) -> 13 | W41: =RIGHT(B41,2) | X41: =RIGHT(C41,2) | Y41: =RIGHT(D41,2) -> 23 | Z41: =RIGHT(E41,2) | AA41: =RIGHT(F41,2) -> 1) | AB41: =RIGHT(G41,2) -> 0) | AC41: =RIGHT(H41,2) -> 1) | ... AM41: =RIGHT(R41,2) -> 1)
A42: Ануфриева/Семенова | D42: Чекан Н.Н. | F42: Каминский Н.В. | G42: Шумило Д.М. | H42: Гордиевич Е.И. | I42: Исакова Н.К. | J42: Буевич С.В. | K42: Гончарова Ю.А. | L42: Федорцова А.Т. | M42: Черненкова И.А. | N42: Якшина О.А. | O42: Страх В.М. | P42: Цыбульская Е.А. | Q42: Гаврилкина Л.П. | R42: Гаврилкина Л.П. | T42: 9.55 - 10.40 2 урок
A43: Устройство авто 55(31) | D43: Спецтехнология (К) 23 | F43: Устр-во тракторов 53 (21) | G43: Черчение 12 (2) | H43: Устр.агр.т.и обор.14(20) | I43: Бел.язык 35(14) | J43: Пр.инф.1/Ин.в пр.2 31/13 | K43: История Беларуси 21(5) | L43: Физика 11 (1) | M43: Физическая культура (Ч) | N43: Рус.язык 34 (13) | O43: Химия 44 (18) | P43: Математика 45 (19) | Q43: Основы права 33(12) | R43: Основы права 33(12) | T43: 10.50 - 11.35 3 урок | V43: =RIGHT(A43,2) -> 1) | W43: =RIGHT(B43,2) | X43: =RIGHT(C43,2) | Y43: =RIGHT(D43,2) -> 23 | Z43: =RIGHT(E43,2) | AA43: =RIGHT(F43,2) -> 1) | AB43: =RIGHT(G43,2) -> 2) | AC43: =RIGHT(H43,2) -> 0) | ... AM43: =RIGHT(R43,2) -> 2)
...

Sheet Понедельник
A1: Расписание занятий
A2: Понедельник
A3: ='На неделю'!D1 -> 46266
A4: ='На неделю'!A2 -> 144 | B4: ='На неделю'!B2 -> 145 | C4: ='На неделю'!C2 -> 146 | D4: ='На неделю'!D2 -> 147 | E4: ='На неделю'!E2 -> 148
A5: ='На неделю'!A4 -> 0 | B5: ='На неделю'!B4 -> 0 | C5: ='На неделю'!C4 -> 0 | D5: ='На неделю'!D4 -> 0 | E5: ='На неделю'!E4 -> 0
A6: ='На неделю'!A5 -> 0 | B6: ='На неделю'!B5 -> 0 | C6: ='На неделю'!C5 -> 0 | D6: ='На неделю'!D5 -> 0 | E6: ='На неделю'!E5 -> 0
A7: ='На неделю'!A6 -> 0 | B7: ='На неделю'!B6 -> 0 | C7: ='На неделю'!C6 -> 0 | D7: ='На неделю'!D6 -> 0 | E7: ='На неделю'!E6 -> 0
A8: ='На неделю'!A7 -> 0 | B8: ='На неделю'!B7 -> 0 | C8: ='На неделю'!C7 -> 0 | D8: ='На неделю'!D7 -> 0 | E8: ='На неделю'!E7 -> 0
A9: ='На неделю'!A8 -> 0 | B9: ='На неделю'!B8 -> 0 | C9: ='На неделю'!C8 -> 0 | D9: ='На неделю'!D8 -> 0 | E9: ='На неделю'!E8 -> 0
A10: ='На неделю'!A9 -> 0 | B10: ='На неделю'!B9 -> 0 | C10: ='На неделю'!C9 -> 0 | D10: ='На неделю'!D9 -> 0 | E10: ='На неделю'!E9 -> 0
A11: ='На неделю'!A10 -> 0 | B11: ='На неделю'!B10 -> 0 | C11: ='На неделю'!C10 -> 0 | D11: ='На неделю'!D10 -> 0 | E11: ='На неделю'!E10 -> 0
A12: ='На неделю'!A11 -> 0 | B12: ='На неделю'!B11 -> 0 | C12: ='На неделю'!C11 -> 0 | D12: ='На неделю'!D11 -> 0 | E12: ='На неделю'!E11 -> 0
A13: ='На неделю'!A12 -> 0 | B13: ='На неделю'!B12 -> 0 | C13: ='На неделю'!C12 -> 0 | D13: ='На неделю'!D12 -> 0 | E13: ='На неделю'!E12 -> 0
A14: ='На неделю'!A13 -> 0 | B14: ='На неделю'!B13 -> 0 | C14: ='На неделю'!C13 -> 0 | D14: ='На неделю'!D13 -> 0 | E14: ='На неделю'!E13 -> 0
A15: ='На неделю'!A14 -> 0 | B15: ='На неделю'!B14 -> 0 | C15: ='На неделю'!C14 -> 0 | D15: ='На неделю'!D14 -> 0 | E15: ='На неделю'!E14 -> 0
A17: ='На неделю'!F2 -> 149 | B17: ='На неделю'!G2 -> 150 | C17: ='На неделю'!H2 -> 151 | D17: ='На неделю'!I2 -> 152 | E17: ='На неделю'!J2 -> 153
A18: ='На неделю'!F4 -> 0 | B18: ='На неделю'!G4 -> 0 | C18: ='На неделю'!H4 -> 0 | D18: ='На неделю'!I4 -> 0 | E18: ='На неделю'!J4 -> 0
A19: ='На неделю'!F5 -> 0 | B19: ='На неделю'!G5 -> 0 | C19: ='На неделю'!H5 -> 0 | D19: ='На неделю'!I5 -> 0 | E19: ='На неделю'!J5 -> 0
A20: ='На неделю'!F6 -> 0 | B20: ='На неделю'!G6 -> 0 | C20: ='На неделю'!H6 -> 0 | D20: ='На неделю'!I6 -> 0 | E20: ='На неделю'!J6 -> 0
A21: ='На неделю'!F7 -> 0 | B21: ='На неделю'!G7 -> 0 | C21: ='На неделю'!H7 -> 0 | D21: ='На неделю'!I7 -> 0 | E21: ='На неделю'!J7 -> 0
A22: ='На неделю'!F8 -> 0 | B22: ='На неделю'!G8 -> 0 | C22: ='На неделю'!H8 -> 0 | D22: ='На неделю'!I8 -> 0 | E22: ='На неделю'!J8 -> 0
A23: ='На неделю'!F9 -> 0 | B23: ='На неделю'!G9 -> 0 | C23: ='На неделю'!H9 -> 0 | D23: ='На неделю'!I9 -> 0 | E23: ='На неделю'!J9 -> 0
A24: ='На неделю'!F10 -> 0 | B24: ='На неделю'!G10 -> 0 | C24: ='На неделю'!H10 -> 0 | D24: ='На неделю'!I10 -> 0 | E24: ='На неделю'!J10 -> 0
A25: ='На неделю'!F11 -> 0 | B25: ='На неделю'!G11 -> 0 | C25: ='На неделю'!H11 -> 0 | D25: ='На неделю'!I11 -> 0 | E25: ='На неделю'!J11 -> 0
A26: ='На неделю'!F12 -> 0 | B26: ='На неделю'!G12 -> 0 | C26: ='На неделю'!H12 -> 0 | D26: ='На неделю'!I12 -> 0 | E26: ='На неделю'!J12 -> 0
A27: ='На неделю'!F13 -> 0 | B27: ='На неделю'!G13 -> 0 | C27: ='На неделю'!H13 -> 0 | D27: ='На неделю'!I13 -> 0 | E27: ='На неделю'!J13 -> 0
A28: ='На неделю'!F14 -> 0 | B28: ='На неделю'!G14 -> 0 | C28: ='На неделю'!H14 -> 0 | D28: ='На неделю'!I14 -> 0 | E28: ='На неделю'!J14 -> 0
A30: ='На неделю'!K2 -> 154 | B30: ='На неделю'!L2 -> 155 | C30: ='На неделю'!M2 -> 156 | D30: ='На неделю'!N2 -> 157 | E30: ='На неделю'!O2 -> 158
A31: ='На неделю'!K4 -> 0 | B31: ='На неделю'!L4 -> 0 | C31: ='На неделю'!M4 -> 0 | D31: ='На неделю'!N4 -> 0 | E31: ='На неделю'!O4 -> 0
A32: ='На неделю'!K5 -> 0 | B32: ='На неделю'!L5 -> 0 | C32: ='На неделю'!M5 -> 0 | D32: ='На неделю'!N5 -> 0 | E32: ='На неделю'!O5 -> 0
A33: ='На неделю'!K6 -> 0 | B33: ='На неделю'!L6 -> 0 | C33: ='На неделю'!M6 -> 0 | D33: ='На неделю'!N6 -> 0 | E33: ='На неделю'!O6 -> 0
A34: ='На неделю'!K7 -> 0 | B34: ='На неделю'!L7 -> 0 | C34: ='На неделю'!M7 -> 0 | D34: ='На неделю'!N7 -> 0 | E34: ='На неделю'!O7 -> 0
A35: ='На неделю'!K8 -> 0 | B35: ='На неделю'!L8 -> 0 | C35: ='На неделю'!M8 -> 0 | D35: ='На неделю'!N8 -> 0 | E35: ='На неделю'!O8 -> 0
A36: ='На неделю'!K9 -> 0 | B36: ='На неделю'!L9 -> 0 | C36: ='На неделю'!M9 -> 0 | D36: ='На неделю'!N9 -> 0 | E36: ='На неделю'!O9 -> 0
A37: ='На неделю'!K10 -> 0 | B37: ='На неделю'!L10 -> 0 | C37: ='На неделю'!M10 -> 0 | D37: ='На неделю'!N10 -> 0 | E37: ='На неделю'!O10 -> 0
A38: ='На неделю'!K11 -> 0 | B38: ='На неделю'!L11 -> 0 | C38: ='На неделю'!M11 -> 0 | D38: ='На неделю'!N11 -> 0 | E38: ='На неделю'!O11 -> 0
A39: ='На неделю'!K12 -> 0 | B39: ='На неделю'!L12 -> 0 | C39: ='На неделю'!M12 -> 0 | D39: ='На неделю'!N12 -> 0 | E39: ='На неделю'!O12 -> 0
A40: ='На неделю'!K13 -> 0 | B40: ='На неделю'!L13 -> 0 | C40: ='На неделю'!M13 -> 0 | D40: ='На неделю'!N13 -> 0 | E40: ='На неделю'!O13 -> 0
A41: ='На неделю'!K14 -> 0 | B41: ='На неделю'!L14 -> 0 | C41: ='На неделю'!M14 -> 0 | D41: ='На неделю'!N14 -> 0 | E41: ='На неделю'!O14 -> 0
A43: ='На неделю'!P2 -> 159 | B43: ='На неделю'!Q2 -> 160 | C43: =Вторник!C43 -> 161 | D43: РАСПИСАНИЕ ЗВОНКОВ
...

Sheet Вторник
A1: Расписание занятий
A2: Вторник
A3: =Понедельник!A3+1 -> 46267
A4: ='На неделю'!A2 -> 144 | B4: ='На неделю'!B2 -> 145 | C4: ='На неделю'!C2 -> 146 | D4: ='На неделю'!D2 -> 147 | E4: ='На неделю'!E2 -> 148
A5: ='На неделю'!A16 -> 0 | B5: ='На неделю'!B16 -> 0 | C5: ='На неделю'!C16 -> 0 | D5: ='На неделю'!D16 -> 0 | E5: ='На неделю'!E16 -> 0
A6: ='На неделю'!A17 -> Линейка | B6: ='На неделю'!B17 -> Линейка | C6: ='На неделю'!C17 -> Линейка | D6: ='На неделю'!D17 -> Линейка | E6: ='На неделю'!E17 -> Линейка
A7: ='На неделю'!A18 -> Курат. Час (библ.) | B7: ='На неделю'!B18 -> Курат. Час 44. | C7: ='На неделю'!C18 -> Курат. Час 53 | D7: ='На неделю'!D18 -> Курат. Час 22 | E7: ='На неделю'!E18 -> Курат. Час 34
A8: ='На неделю'!A19 -> ТО и Р ТС 53 | B8: ='На неделю'!B19 -> Устройство авто 54 | C8: ='На неделю'!C19 -> Маш. и обор. живот. 51 | D8: ='На неделю'!D19 -> Калькул. и уч 14 | E8: ='На неделю'!E19 -> 0
A9: ='На неделю'!A20 -> Гордиевич Е.И. | B9: ='На неделю'!B20 -> Каминский Н.В. | C9: ='На неделю'!C20 -> Шумило Д.М. | D9: ='На неделю'!D20 -> Концевая Т.В. | E9: ='На неделю'!E21 -> П/О
A10: ='На неделю'!A21 -> Устройство авто 54 | B10: ='На неделю'!B21 -> Маш. и обор. живот. 51 | C10: ='На неделю'!C21 -> Физическая культ | D10: ='На неделю'!D21 -> Спецтехнология (К) 23 | E10: ='На неделю'!E22 -> 0
A11: ='На неделю'!A22 -> Каминский Н.В. | B11: ='На неделю'!B22 -> Шумило Д.М. | C11: ='На неделю'!C22 -> Козенков | D11: ='На неделю'!D22 -> Чекан Н.Н. | E11: ='На неделю'!E22 -> 0
A12: ='На неделю'!A23 -> 0 | B12: ='На неделю'!B23 -> Устр. самоход. маш. 20 | C12: ='На неделю'!C23 -> ТО и Р ТС 53 | D12: ='На неделю'!D23 -> 0 | E12: ='На неделю'!E23 -> 0
A13: ='На неделю'!A24 -> 0 | B13: ='На неделю'!B24 -> Шумило Д.М. | C13: ='На неделю'!C24 -> Гордиевич Е.И. | D13: ='На неделю'!D24 -> 0 | E13: ='На неделю'!E24 -> 0
A14: ='На неделю'!A25 -> 0 | B14: ='На неделю'!B25 -> 0 | C14: ='На неделю'!C25 -> 0 | D14: ='На неделю'!D25 -> 0 | E14: ='На неделю'!E25 -> 0
A15: ='На неделю'!A26 -> 0 | B15: ='На неделю'!B26 -> 0 | C15: ='На неделю'!C26 -> 0 | D15: ='На неделю'!D26 -> 0 | E15: ='На неделю'!E26 -> 0
A17: ='На неделю'!F2 -> 149 | B17: ='На неделю'!G2 -> 150 | C17: ='На неделю'!H2 -> 151 | D17: ='На неделю'!I2 -> 152 | E17: ='На неделю'!J2 -> 153
A18: ='На неделю'!F16 -> 0 | B18: ='На неделю'!G16 -> 0 | C18: ='На неделю'!H16 -> 0 | D18: ='На неделю'!I16 -> 0 | E18: ='На неделю'!J16 -> 0
A19: ='На неделю'!F17 -> Линейка | B19: ='На неделю'!G17 -> Линейка | C19: ='На неделю'!H17 -> Линейка | D19: ='На неделю'!I17 -> Линейка | E19: ='На неделю'!J17 -> Линейка
A20: ='На неделю'!F18 -> Курат. Час 51 | B20: ='На неделю'!G18 -> Курат. Час 54 | C20: ='На неделю'!H18 -> Курат. Час 21 | D20: ='На неделю'!I18 -> Курат. Час 35 | E20: ='На неделю'!J18 -> Курат. Час 13
A21: ='На неделю'!F19 -> 0 | B21: ='На неделю'!G19 -> Обществоведение 33 | C21: ='На неделю'!H19 -> Пр.черчение 12 | D21: ='На неделю'!I19 -> Бел.литература 35 | E21: ='На неделю'!J19 -> Рисоване и лепка 11
A22: ='На неделю'!F20 -> 0 | B22: ='На неделю'!G20 -> Якшина О.А. | C22: ='На неделю'!H20 -> Цыбульская Е.А. | D22: ='На неделю'!I20 -> Черненкова И.А. | E22: ='На неделю'!J20 -> Ероха Е.В.
A23: ='На неделю'!F21 -> П/О | B23: ='На неделю'!G21 -> Охрана труда 12(Ц) | C23: ='На неделю'!H21 -> Устр-во тракторов 53 | D23: ='На неделю'!I21 -> Физическая культ. (Зен.) | E23: ='На неделю'!J21 -> История Беларуси 21
A24: ='На неделю'!F22 -> 0 | B24: ='На неделю'!G22 -> Физическая культ. (Ч) | C24: ='На неделю'!H22 -> Гордиевич Е.И. | D24: ='На неделю'!I22 -> Пр.черчение 12 | E24: ='На неделю'!J22 -> Сушинская Н.В.
A25: ='На неделю'!F23 -> 0 | B25: ='На неделю'!G23 -> 0 | C25: ='На неделю'!H23 -> 0 | D25: ='На неделю'!I23 -> 0 | E25: ='На неделю'!J23 -> 0
A26: ='На неделю'!F24 -> 0 | B26: ='На неделю'!G24 -> 0 | C26: ='На неделю'!H24 -> 0 | D26: ='На неделю'!I24 -> 0 | E26: ='На неделю'!J24 -> 0
A27: ='На неделю'!F25 -> 0 | B27: ='На неделю'!G25 -> 0 | C27: ='На неделю'!H25 -> 0 | D27: ='На неделю'!I25 -> 0 | E27: ='На неделю'!J25 -> 0
A28: ='На неделю'!F26 -> 0 | B28: ='На неделю'!G26 -> 0 | C28: ='На неделю'!H26 -> 0 | D28: ='На неделю'!I26 -> 0 | E28: ='На неделю'!J26 -> 0
A30: ='На неделю'!K2 -> 154 | B30: ='На неделю'!L2 -> 155 | C30: ='На неделю'!M2 -> 156 | D30: ='На неделю'!N2 -> 157 | E30: ='На неделю'!O2 -> 158
A31: ='На неделю'!K16 -> 0 | B31: ='На неделю'!L16 -> 0 | C31: ='На неделю'!M16 -> 0 | D31: ='На неделю'!N16 -> 0 | E31: ='На неделю'!O16 -> 0
A32: ='На неделю'!K17 -> Линейка | B32: ='На неделю'!L17 -> Линейка | C32: ='На неделю'!M17 -> Линейка | D32: ='На неделю'!N17 -> Линейка | E32: ='На неделю'!O17 -> Линейка
A33: ='На неделю'!K18 -> Курат. Час 45 | B33: ='На неделю'!L18 -> Курат. Час 12 | C33: ='На неделю'!M18 -> Курат. Час 33 | D33: ='На неделю'!N18 -> (25) Курат. Час | E33: ='На неделю'!O18 -> Курат. Час 31
A34: ='На неделю'!K19 -> История Беларуси 21 | B34: ='На неделю'!L19 -> Торг. оборудование 24 | C34: ='На неделю'!M19 -> Математика 41 | D34: ='На неделю'!N19 -> Допр. Подготовка 25 | E34: ='На неделю'!O19 -> Русск. Лит 34
A35: ='На неделю'!K20 -> Сушинская Н.В. | B35: ='На неделю'!L20 -> Осипова Н.А. | C35: ='На неделю'!M20 -> Артеменко А.А. | D35: ='На неделю'!N20 -> Смирнов А.Н. | E35: ='На неделю'!O20 -> Исакова Н.К.
A36: ='На неделю'!K21 -> Обществоведение 33 | B36: ='На неделю'!L21 -> Химия 44 | C36: ='На неделю'!M21 -> Допр. Подготовка 25 | D36: ='На неделю'!N21 -> Физика 41 | E36: ='На неделю'!O21 -> Математика 45
A37: ='На неделю'!K22 -> Якшина О.А. | B37: ='На неделю'!L22 -> Федорцова А.Т. | C37: ='На неделю'!M22 -> Смирнов А.Н. | D37: ='На неделю'!N22 -> Артеменко А.А. | E37: ='На неделю'!O22 -> Гончарова Ю.А.
A38: ='На неделю'!K23 -> 0 | B38: ='На неделю'!L23 -> 0 | C38: ='На неделю'!M23 -> 0 | D38: ='На неделю'!O21 -> Математика 45 | E38: ='На неделю'!O23 -> Физическая культ. (С)
A39: ='На неделю'!K24 -> 0 | B39: ='На неделю'!L24 -> 0 | C39: ='На неделю'!M24 -> 0 | D39: ='На неделю'!O22 -> Гончарова Ю.А. | E39: ='На неделю'!O24 -> 0
A40: ='На неделю'!K25 -> 0 | B40: ='На неделю'!L25 -> 0 | C40: ='На неделю'!M25 -> 0 | D40: ='На неделю'!N25 -> 0 | E40: ='На неделю'!O25 -> 0
A41: ='На неделю'!K26 -> 0 | B41: ='На неделю'!L26 -> 0 | C41: ='На неделю'!M26 -> 0 | D41: ='На неделю'!N26 -> 0 | E41: ='На неделю'!O26 -> 0
A43: ='На неделю'!P2 -> 159 | B43: ='На неделю'!Q2 -> 160 | C43: ='На неделю'!R2 -> 161 | D43: РАСПИСАНИЕ ЗВОНКОВ
...

Sheet Среда
A1: Расписание занятий
A2: Среда
A3: =Вторник!A3+1 -> 46268
A4: ='На неделю'!A2 -> 144 | B4: ='На неделю'!B2 -> 145 | C4: ='На неделю'!C2 -> 146 | D4: ='На неделю'!D2 -> 147 | E4: ='На неделю'!E2 -> 148
A5: ='На неделю'!A28 -> 0 | B5: ='На неделю'!B28 -> 0 | C5: ='На неделю'!C28 -> 0 | D5: ='На неделю'!D28 -> 0 | E5: ='На неделю'!E28 -> 0
A6: ='На неделю'!A29 -> Пр.инф.2/Ин.в пр.1 31/43 | B6: ='На неделю'!B29 -> 0 | C6: ='На неделю'!C29 -> 0 | D6: ='На неделю'!D29 -> Спецтехнология (П) 22 | E6: ='На неделю'!E29 -> 0
A7: ='На неделю'!A30 -> Ануфриева/Степанова | B7: ='На неделю'!B30 -> 0 | C7: ='На неделю'!C30 -> 0 | D7: ='На неделю'!D30 -> Голубева Н.И. | E7: ='На неделю'!E30 -> 0
A8: ='На неделю'!A31 -> Устройство авто 55(31) | B8: ='На неделю'!B31 -> 0 | C8: ='На неделю'!C31 -> 0 | D8: ='На неделю'!D31 -> Спецтехнология (П) 22 | E8: ='На неделю'!E31 -> 0
A9: ='На неделю'!A32 -> Каминский Н.В. | B9: ='На неделю'!B32 -> ПП | C9: ='На неделю'!C32 -> ПО | D9: ='На неделю'!D32 -> Голубева Н.И. | E9: ='На неделю'!E32 -> П/О
A10: ='На неделю'!A33 -> ТО и Р авто 55(31) | B10: ='На неделю'!B33 -> 0 | C10: ='На неделю'!C33 -> 0 | D10: ='На неделю'!D33 -> Спецтехнология (К) 23 | E10: ='На неделю'!E33 -> Торг. вычисления 42 (16)
A11: ='На неделю'!A34 -> Каминский Н.В. | B11: ='На неделю'!B34 -> 0 | C11: ='На неделю'!C34 -> 0 | D11: ='На неделю'!D34 -> Чекан Н.Н. | E11: ='На неделю'!E34 -> Осипова Н.А.
A12: ='На неделю'!A35 -> Пр.инф.1/Ин.в пр.2 31/13 | B12: ='На неделю'!B35 -> 0 | C12: ='На неделю'!C35 -> 0 | D12: ='На неделю'!D35 -> Спецтехнология (К) 23 | E12: ='На неделю'!E35 -> 0
A13: ='На неделю'!A36 -> Ануфриева/Семенова | B13: ='На неделю'!B36 -> 0 | C13: ='На неделю'!C36 -> 0 | D13: ='На неделю'!D36 -> Чекан Н.Н. | E13: ='На неделю'!E36 -> 0
A14: ='На неделю'!A37 -> 0 | B14: ='На неделю'!B37 -> 0 | C14: ='На неделю'!C37 -> 0 | D14: ='На неделю'!D37 -> 0 | E14: ='На неделю'!E37 -> 0
A15: ='На неделю'!A38 -> 0 | B15: ='На неделю'!B38 -> 0 | C15: ='На неделю'!C38 -> 0 | D15: ='На неделю'!D38 -> 0 | E15: ='На неделю'!E38 -> 0
A17: ='На неделю'!F2 -> 149 | B17: ='На неделю'!G2 -> 150 | C17: ='На неделю'!H2 -> 151 | D17: ='На неделю'!I2 -> 152 | E17: ='На неделю'!J2 -> 153
A18: ='На неделю'!F28 -> 0 | B18: ='На неделю'!G28 -> 0 | C18: ='На неделю'!H28 -> 0 | D18: ='На неделю'!I28 -> 0 | E18: ='На неделю'!J28 -> 0
A19: ='На неделю'!F29 -> Черчение 12 (2) | B19: ='На неделю'!G29 -> Устр.агр.т.и обор.14(20) | C19: ='На неделю'!H29 -> Устр-во тракторов 53 (21) | D19: ='На неделю'!I29 -> Физ. культура (Ст/Ч) | E19: ='На неделю'!J29 -> Бел.язык 35(14)
A20: ='На неделю'!F30 -> Цыбульская Е.А. | B20: ='На неделю'!G30 -> Шумило Д.М. | C20: ='На неделю'!H30 -> Гордиевич Е.И. | D20: ='На неделю'!I30 -> Бел.язык 35(14) | E20: ='На неделю'!J30 -> Физ. культура (Ст/Ч)
A21: ='На неделю'!F31 -> Устр.агр.т.и обор.14(20) | B21: ='На неделю'!G31 -> Устр-во тракторов 53 (21) | C21: ='На неделю'!H31 -> Черчение 12 (2) | D21: ='На неделю'!I31 -> Пр.инф.2/Ин.в пр.1 31/43 | E21: ='На неделю'!J31 -> История Беларуси 21(5)
A22: ='На неделю'!F32 -> Шумило Д.М. | B22: ='На неделю'!G32 -> Гордиевич Е.И. | C22: ='На неделю'!H32 -> Цыбульская Е.А. | D22: ='На неделю'!I32 -> Ануфриева/Степанова | E22: ='На неделю'!J32 -> Сушинская Н.В.
A23: ='На неделю'!F33 -> Устр-во тракторов 53 (21) | B23: ='На неделю'!G33 -> Математика 41 (15) | C23: ='На неделю'!H33 -> Устр.агр.т.и обор.14(20) | D23: ='На неделю'!I33 -> Пр.инф.1/Ин.в пр.2 31/13 | E23: ='На неделю'!J33 -> Торг. вычисления 42 (16)
A24: ='На неделю'!F34 -> Гордиевич Е.И. | B24: ='На неделю'!G34 -> Артеменко А.А. | C24: ='На неделю'!H34 -> Шумило Д.М. | D24: ='На неделю'!I34 -> Ануфриева/Семенова | E24: ='На неделю'!J34 -> Осипова Н.А.
A25: ='На неделю'!F35 -> -------------------------------- | B25: ='На неделю'!G35 -> -------------------------------- | C25: ='На неделю'!H35 -> -------------------------------- | D25: ='На неделю'!I35 -> -------------------------------- | E25: ='На неделю'!J35 -> --------------------------------
A26: ='На неделю'!F36 -> -------------------------------- | B26: ='На неделю'!G36 -> -------------------------------- | C26: ='На неделю'!H36 -> -------------------------------- | D26: ='На неделю'!I36 -> -------------------------------- | E26: ='На неделю'!J36 -> --------------------------------
A27: ='На неделю'!F37 -> 0 | B27: ='На неделю'!G37 -> 0 | C27: ='На неделю'!H37 -> 0 | D27: ='На неделю'!I37 -> 0 | E27: ='На неделю'!J37 -> 0
A28: ='На неделю'!F38 -> 0 | B28: ='На неделю'!G38 -> 0 | C28: ='На неделю'!H38 -> 0 | D28: ='На неделю'!I38 -> 0 | E28: ='На неделю'!J38 -> 0
A30: ='На неделю'!K2 -> 154 | B30: ='На неделю'!L2 -> 155 | C30: ='На неделю'!M2 -> 156 | D30: ='На неделю'!N2 -> 157 | E30: ='На неделю'!O2 -> 158
A31: ='На неделю'!K28 -> 0 | B31: ='На неделю'!L28 -> 0 | C31: ='На неделю'!M28 -> 0 | D31: ='На неделю'!N28 -> 0 | E31: ='На неделю'!O28 -> 0
A32: ='На неделю'!K29 -> Математика 45 (19) | B32: ='На неделю'!L29 -> Биология 32 (11) | C32: ='На неделю'!M29 -> Химия 44 (18) | D32: ='На неделю'!N29 -> История Беларуси 21(5) | E32: ='На неделю'!O29 -> ЗНТЧС 25(9)
A33: ='На неделю'!K30 -> Гончарова Ю.А. | B33: ='На неделю'!L30 -> Буевич С.В. | C33: ='На неделю'!M30 -> Федорцова А.Т. | D33: ='На неделю'!N30 -> Сушинская Н.В. | E33: ='На неделю'!O30 -> Страх В.М.
A34: ='На неделю'!K31 -> Физ. культура (Ст/Ч) | B34: ='На неделю'!L31 -> Основы права 33(12) | C34: ='На неделю'!M31 -> Математика 45 (19) | D34: ='На неделю'!N31 -> Математика 41 (15) | E34: ='На неделю'!O31 -> Рус.язык 34 (13)
A35: ='На неделю'!K32 -> Рус.язык 34 (13) | B35: ='На неделю'!L32 -> Якшина О.А. | C35: ='На неделю'!M32 -> Гончарова Ю.А. | D35: ='На неделю'!N32 -> Артеменко А.А. | E35: ='На неделю'!O32 -> Физ. культура (Ст/Ч)
A36: ='На неделю'!K33 -> Обществоведение 33(12) | B36: ='На неделю'!L33 -> Бел.язык 35(14) | C36: ='На неделю'!M33 -> Биология 32 (11) | D36: ='На неделю'!N33 -> Химия 44 (18) | E36: ='На неделю'!O33 -> Физика 11 (1)
A37: ='На неделю'!K34 -> Якшина О.А. | B37: ='На неделю'!L34 -> Черненкова И.А. | C37: ='На неделю'!M34 -> Буевич С.В. | D37: ='На неделю'!N34 -> Федорцова А.Т. | E37: ='На неделю'!O34 -> Гаврилкина Л.П.
A38: ='На неделю'!K35 -> -------------------------------- | B38: ='На неделю'!L35 -> -------------------------------- | C38: ='На неделю'!M35 -> -------------------------------- | D38: ='На неделю'!N35 -> -------------------------------- | E38: ='На неделю'!O35 -> --------------------------------
A39: ='На неделю'!K36 -> -------------------------------- | B39: ='На неделю'!L36 -> -------------------------------- | C39: ='На неделю'!M36 -> -------------------------------- | D39: ='На неделю'!N36 -> -------------------------------- | E39: ='На неделю'!O36 -> --------------------------------
A40: ='На неделю'!K37 -> 0 | B40: ='На неделю'!L37 -> 0 | C40: ='На неделю'!M37 -> 0 | D40: ='На неделю'!N37 -> 0 | E40: ='На неделю'!O37 -> 0
A41: ='На неделю'!K38 -> 0 | B41: ='На неделю'!L38 -> 0 | C41: ='На неделю'!M38 -> 0 | D41: ='На неделю'!N38 -> 0 | E41: ='На неделю'!O38 -> 0
A43: ='На неделю'!P2 -> 159 | B43: ='На неделю'!Q2 -> 160 | C43: ='На неделю'!R2 -> 161 | D43: РАСПИСАНИЕ ЗВОНКОВ
...

Sheet Четверг
A1: Расписание занятий
A2: Четверг
A3: =Среда!A3+1 -> 46269
A4: ='На неделю'!A2 -> 144 | B4: ='На неделю'!B2 -> 145 | C4: ='На неделю'!C2 -> 146 | D4: ='На неделю'!D2 -> 147 | E4: ='На неделю'!E2 -> 148
A5: ='На неделю'!A40 -> 0 | B5: ='На неделю'!B40 -> 0 | C5: ='На неделю'!C40 -> 0 | D5: ='На неделю'!D40 -> 0 | E5: ='На неделю'!E40 -> 0
A6: ='На неделю'!A41 -> Пр.инф.1/Ин.в пр.2 31/13 | B6: ='На неделю'!B41 -> 0 | C6: ='На неделю'!C41 -> 0 | D6: ='На неделю'!D41 -> Спецтехнология (К) 23 | E6: ='На неделю'!E41 -> 0
A7: ='На неделю'!A42 -> Ануфриева/Семенова | B7: ='На неделю'!B42 -> 0 | C7: ='На неделю'!C42 -> 0 | D7: ='На неделю'!D42 -> Чекан Н.Н. | E7: ='На неделю'!E42 -> 0
A8: ='На неделю'!A43 -> Устройство авто 55(31) | B8: ='На неделю'!B43 -> 0 | C8: ='На неделю'!C43 -> 0 | D8: ='На неделю'!D43 -> Спецтехнология (К) 23 | E8: ='На неделю'!E43 -> 0
A9: ='На неделю'!A44 -> Каминский Н.В. | B9: ='На неделю'!B44 -> ПП | C9: ='На неделю'!C44 -> ПО | D9: ='На неделю'!D44 -> Чекан Н.Н. | E9: ='На неделю'!E44 -> П/О
A10: ='На неделю'!A45 -> Пр.инф.2/Ин.в пр.1 31/43 | B10: ='На неделю'!B45 -> 0 | C10: ='На неделю'!C45 -> 0 | D10: ='На неделю'!D45 -> Спецтехнология (П) 22 | E10: ='На неделю'!E45 -> Мастерская
A11: ='На неделю'!A46 -> Ануфриева/Степанова | B11: ='На неделю'!B46 -> 0 | C11: ='На неделю'!C46 -> 0 | D11: ='На неделю'!D46 -> Голубева Н.И. | E11: ='На неделю'!E46 -> "Учебный
A12: ='На неделю'!A47 -> ТО и Р тр-ров 53 (21) | B12: ='На неделю'!B47 -> 0 | C12: ='На неделю'!C47 -> 0 | D12: ='На неделю'!D47 -> Спецтехнология (П) 22 | E12: ='На неделю'!E47 -> магазин"
A13: ='На неделю'!A48 -> Гордиевич Е.И. | B13: ='На неделю'!B48 -> 0 | C13: ='На неделю'!C48 -> 0 | D13: ='На неделю'!D48 -> Голубева Н.И. | E13: ='На неделю'!E48 -> 0
A14: ='На неделю'!A49 -> 0 | B14: ='На неделю'!B49 -> 0 | C14: ='На неделю'!C49 -> 0 | D14: ='На неделю'!D49 -> 0 | E14: ='На неделю'!E49 -> 0
A15: ='На неделю'!A50 -> 0 | B15: ='На неделю'!B50 -> 0 | C15: ='На неделю'!C50 -> 0 | D15: ='На неделю'!D50 -> 0 | E15: ='На неделю'!E50 -> 0
A17: ='На неделю'!F2 -> 149 | B17: ='На неделю'!G2 -> 150 | C17: ='На неделю'!H2 -> 151 | D17: ='На неделю'!I2 -> 152 | E17: ='На неделю'!J2 -> 153
A18: ='На неделю'!F40 -> 0 | B18: ='На неделю'!G40 -> 0 | C18: ='На неделю'!H40 -> 0 | D18: ='На неделю'!I40 -> 0 | E18: ='На неделю'!J40 -> 0
A19: ='На неделю'!F41 -> Устройство авто 55(31) | B19: ='На неделю'!G41 -> Устр.агр.т.и обор.14(20) | C19: ='На неделю'!H41 -> Устр-во тракторов 53 (21) | D19: ='На неделю'!I41 -> Рус.литература 34 (13) | E19: ='На неделю'!J41 -> География 32 (11)
A20: ='На неделю'!F42 -> Каминский Н.В. | B20: ='На неделю'!G42 -> Шумило Д.М. | C20: ='На неделю'!H42 -> Гордиевич Е.И. | D20: ='На неделю'!I42 -> Исакова Н.К. | E20: ='На неделю'!J42 -> Буевич С.В.
A21: ='На неделю'!F43 -> Устр-во тракторов 53 (21) | B21: ='На неделю'!G43 -> Черчение 12 (2) | C21: ='На неделю'!H43 -> Устр.агр.т.и обор.14(20) | D21: ='На неделю'!I43 -> Бел.язык 35(14) | E21: ='На неделю'!J43 -> Пр.инф.1/Ин.в пр.2 31/13
A22: ='На неделю'!F44 -> Гордиевич Е.И. | B22: ='На неделю'!G44 -> Цыбульская Е.А. | C22: ='На неделю'!H44 -> Шумило Д.М. | D22: ='На неделю'!I44 -> Черненкова И.А. | E22: ='На неделю'!J44 -> Ануфриева/Семенова
A23: ='На неделю'!F45 -> Устр.агр.т.и обор.14(20) | B23: ='На неделю'!G45 -> Устр-во тракторов 53 (21) | C23: ='На неделю'!H45 -> Рус. литература 34(13) | D23: ='На неделю'!I45 -> Товаров.пищ.пр.42 (16) | E23: ='На неделю'!J45 -> ЗНТЧС 25(9)
A24: ='На неделю'!F46 -> Шумило Д.М. | B24: ='На неделю'!G46 -> Гордиевич Е.И. | C24: ='На неделю'!H46 -> Физическая культура (Ч) | D24: ='На неделю'!I46 -> Осипова Н.А. | E24: ='На неделю'!J46 -> Страх В.М.
A25: ='На неделю'!F47 -> Бел.язык 35(14) | B25: ='На неделю'!G47 -> Физическая культура (Ч) | C25: ='На неделю'!H47 -> История Беларуси 21(5) | D25: ='На неделю'!I47 -> Астрономия 45 (19) | E25: ='На неделю'!J47 -> Пр.инф.2/Ин.в пр.1 31/43
A26: ='На неделю'!F48 -> Физическая культура (Ч) | B26: ='На неделю'!G48 -> -------------------------------- | C26: ='На неделю'!H48 -> Сушинская Н.В. | D26: ='На неделю'!I48 -> -------------------------------- | E26: ='На неделю'!J48 -> Ануфриева/Степанова
A27: ='На неделю'!F49 -> 0 | B27: ='На неделю'!G49 -> 0 | C27: ='На неделю'!H49 -> 0 | D27: ='На неделю'!I49 -> 0 | E27: ='На неделю'!J49
A28: ='На неделю'!F50 -> 0 | B28: ='На неделю'!G50 -> 0 | C28: ='На неделю'!H50 -> 0 | D28: ='На неделю'!I50 -> 0 | E28: ='На неделю'!J50 -> 0
A30: ='На неделю'!K2 -> 154 | B30: ='На неделю'!L2 -> 155 | C30: ='На неделю'!M2 -> 156 | D30: ='На неделю'!N2 -> 157 | E30: ='На неделю'!O2 -> 158
A31: ='На неделю'!K40 -> 0 | B31: ='На неделю'!L40 -> 0 | C31: ='На неделю'!M40 -> 0 | D31: ='На неделю'!N40 -> 0 | E31: ='На неделю'!O40 -> 0
A32: ='На неделю'!K41 -> Астрономия 45 (19) | B32: ='На неделю'!L41 -> Химия 44 (18) | C32: ='На неделю'!M41 -> Бел.литература 35(14) | D32: ='На неделю'!N41 -> Основы права 33(12) | E32: ='На неделю'!O41 -> ЗНТЧС 25(9)
A33: ='На неделю'!K42 -> Гончарова Ю.А. | B33: ='На неделю'!L42 -> Федорцова А.Т. | C33: ='На неделю'!M42 -> Черненкова И.А. | D33: ='На неделю'!N42 -> Якшина О.А. | E33: ='На неделю'!O42 -> Страх В.М.
A34: ='На неделю'!K43 -> История Беларуси 21(5) | B34: ='На неделю'!L43 -> Физика 11 (1) | C34: ='На неделю'!M43 -> Физическая культура (Ч) | D34: ='На неделю'!N43 -> Рус.язык 34 (13) | E34: ='На неделю'!O43 -> Химия 44 (18)
A35: ='На неделю'!K44 -> Сушинская Н.В. | B35: ='На неделю'!L44 -> Гаврилкина Л.П. | C35: ='На неделю'!M44 -> Рус.язык 34 (13) | D35: ='На неделю'!N44 -> Физическая культура (Ч) | E35: ='На неделю'!O44 -> Федорцова А.Т.
A36: ='На неделю'!K45 -> Математика 45 (19) | B36: ='На неделю'!L45 -> Физическая культура (Ч) | C36: ='На неделю'!M45 -> Физика 11 (1) | D36: ='На неделю'!N45 -> География 32 (11) | E36: ='На неделю'!O45 -> История Беларуси 21(5)
A37: ='На неделю'!K46 -> Гончарова Ю.А. | B37: ='На неделю'!L46 -> Рус. литература 34(13) | C37: ='На неделю'!M46 -> Гаврилкина Л.П. | D37: ='На неделю'!N46 -> Буевич С.В. | E37: ='На неделю'!O46 -> Сушинская Н.В.
A38: ='На неделю'!K47 -> Электротехника 14 (20) | B38: ='На неделю'!L47 -> Основы права 33(12) | C38: ='На неделю'!M47 -> Черчение 12(2) | D38: ='На неделю'!N47 -> Физика 11 (1) | E38: ='На неделю'!O47 -> Биология 44 (18)
A39: ='На неделю'!K48 -> Земец И.И. | B39: ='На неделю'!L48 -> -------------------------------- | C39: ='На неделю'!M48 -> -------------------------------- | D39: ='На неделю'!N48 -> Гаврилкина Л.П. | E39: ='На неделю'!O48 -> Федорцова А.Т.
A40: ='На неделю'!K49 -> 0 | B40: ='На неделю'!L49 -> 0 | C40: ='На неделю'!M49 -> 0 | D40: ='На неделю'!N49 -> 0 | E40: ='На неделю'!O49 -> 0
A41: ='На неделю'!K50 -> 0 | B41: ='На неделю'!L50 -> 0 | C41: ='На неделю'!M50 -> 0 | D41: ='На неделю'!N50 -> 0 | E41: ='На неделю'!O50 -> 0
A43: ='На неделю'!P2 -> 159 | B43: ='На неделю'!Q2 -> 160 | C43: ='На неделю'!R2 -> 161 | D43: РАСПИСАНИЕ ЗВОНКОВ
...

Sheet Пятница
A1: Расписание занятий
A2: Пятница
A3: =Четверг!A3+1 -> 46270
A4: ='На неделю'!A2 -> 144 | B4: ='На неделю'!B2 -> 145 | C4: ='На неделю'!C2 -> 146 | D4: ='На неделю'!D2 -> 147 | E4: ='На неделю'!E2 -> 148
A5: ='На неделю'!A52 -> 8.05 Физ. культура (Ч) | B5: ='На неделю'!B52 -> 0 | C5: ='На неделю'!C52 -> 0 | D5: ='На неделю'!D52 -> 0 | E5: ='На неделю'!E52 -> 0
A6: ='На неделю'!A53 -> Устройство авто 55(31) | B6: ='На неделю'!B53 -> 0 | C6: ='На неделю'!C53 -> 0 | D6: ='На неделю'!D53 -> Спецтехнология (К) 23 | E6: ='На неделю'!E53 -> 0
A7: ='На неделю'!A54 -> Каминский Н.В. | B7: ='На неделю'!B54 -> 0 | C7: ='На неделю'!C54 -> 0 | D7: ='На неделю'!D54 -> Чекан Н.Н. | E7: ='На неделю'!E54 -> 0
A8: ='На неделю'!A55 -> ТО и Р авто 55(31) | B8: ='На неделю'!B55 -> 0 | C8: ='На неделю'!C55 -> 0 | D8: ='На неделю'!D55 -> Спецтехнология (К) 23 | E8: ='На неделю'!E55 -> 0
A9: ='На неделю'!A56 -> Каминский Н.В. | B9: ='На неделю'!B56 -> ПП | C9: ='На неделю'!C56 -> ПО | D9: ='На неделю'!D56 -> Чекан Н.Н. | E9: ='На неделю'!E56 -> П/О
A10: ='На неделю'!A57 -> ТО и Р авто 55(31) | B10: ='На неделю'!B57 -> 0 | C10: ='На неделю'!C57 -> 0 | D10: ='На неделю'!D57 -> Физическая культура | E10: ='На неделю'!E57 -> Мастерская
A11: ='На неделю'!A58 -> Каминский Н.В. | B11: ='На неделю'!B58 -> 0 | C11: ='На неделю'!C58 -> 0 | D11: ='На неделю'!D58 -> Чевидаев/Столбицкий | E11: ='На неделю'!E58 -> "Учебный
A12: ='На неделю'!A59 -> -------------------------------- | B12: ='На неделю'!B59 -> 0 | C12: ='На неделю'!C59 -> 0 | D12: ='На неделю'!D59 -> -------------------------------- | E12: ='На неделю'!E59 -> магазин"
A13: ='На неделю'!A60 -> -------------------------------- | B13: ='На неделю'!B60 -> 0 | C13: ='На неделю'!C60 -> 0 | D13: ='На неделю'!D60 -> -------------------------------- | E13: ='На неделю'!E60 -> 0
A14: ='На неделю'!A61 -> 0 | B14: ='На неделю'!B61 -> 0 | C14: ='На неделю'!C61 -> 0 | D14: ='На неделю'!D61 -> 0 | E14: ='На неделю'!E61 -> 0
A15: ='На неделю'!A62 -> 0 | B15: ='На неделю'!B62 -> 0 | C15: ='На неделю'!C62 -> 0 | D15: ='На неделю'!D62 -> 0 | E15: ='На неделю'!E62 -> 0
A17: ='На неделю'!F2 -> 149 | B17: ='На неделю'!G2 -> 150 | C17: ='На неделю'!H2 -> 151 | D17: ='На неделю'!I2 -> 152 | E17: ='На неделю'!J2 -> 153
A18: ='На неделю'!F52 -> 0 | B18: ='На неделю'!G52 -> 0 | C18: ='На неделю'!H52 -> 0 | D18: ='На неделю'!I52 -> 0 | E18: ='На неделю'!J52 -> 0
A19: ='На неделю'!F53 -> Устр-во тракторов 53 (21) | B19: ='На неделю'!G53 -> Математика 41 (15) | C19: ='На неделю'!H53 -> Обществоведение 33(12) | D19: ='На неделю'!I53 -> Пр.инф.2/Ин.в пр.1 31/43 | E19: ='На неделю'!J53 -> Математика 45 (19)
A20: ='На неделю'!F54 -> Гордиевич Е.И. | B20: ='На неделю'!G54 -> Артеменко А.А. | C20: ='На неделю'!H54 -> Якшина О.А. | D20: ='На неделю'!I54 -> Ануфриева/Степанова | E20: ='На неделю'!J54 -> Гончарова Ю.А.
A21: ='На неделю'!F55 -> Обществоведение 33(12) | B21: ='На неделю'!G55 -> Устр-во тракторов 53 (21) | C21: ='На неделю'!H55 -> Математика 41 (15) | D21: ='На неделю'!I55 -> Физ. культура (Ст/Ч) | E21: ='На неделю'!J55 -> История Беларуси 21(5)
A22: ='На неделю'!F56 -> Якшина О.А. | B22: ='На неделю'!G56 -> Гордиевич Е.И. | C22: ='На неделю'!H56 -> Артеменко А.А. | D22: ='На неделю'!I56 -> История Беларуси 21(5) | E22: ='На неделю'!J56 -> Физ. культура (Ст/Ч)
A23: ='На неделю'!F57 -> Математика 41 (15) | B23: ='На неделю'!G57 -> Обществоведение 33(12) | C23: ='На неделю'!H57 -> Устр-во тракторов 53 (21) | D23: ='На неделю'!I57 -> Пр.инф.1/Ин.в пр.2 31/13 | E23: ='На неделю'!J57 -> Торг. вычисления 42 (16)
A24: ='На неделю'!F58 -> Артеменко А.А. | B24: ='На неделю'!G58 -> Якшина О.А. | C24: ='На неделю'!H58 -> Гордиевич Е.И. | D24: ='На неделю'!I58 -> Ануфриева/Семенова | E24: ='На неделю'!J58 -> Осипова Н.А.
A25: ='На неделю'!F59 -> -------------------------------- | B25: ='На неделю'!G59 -> -------------------------------- | C25: ='На неделю'!H59 -> -------------------------------- | D25: ='На неделю'!I59 -> -------------------------------- | E25: ='На неделю'!J59 -> --------------------------------
A26: ='На неделю'!F60 -> -------------------------------- | B26: ='На неделю'!G60 -> -------------------------------- | C26: ='На неделю'!H60 -> -------------------------------- | D26: ='На неделю'!I60 -> -------------------------------- | E26: ='На неделю'!J60 -> --------------------------------
A27: ='На неделю'!F61 -> 0 | B27: ='На неделю'!G61 -> 0 | C27: ='На неделю'!H61 -> 0 | D27: ='На неделю'!I61 -> 0 | E27: ='На неделю'!J61 -> 0
A28: ='На неделю'!F62 -> 0 | B28: ='На неделю'!G62 -> 0 | C28: ='На неделю'!H62 -> 0 | D28: ='На неделю'!I62 -> 0 | E28: ='На неделю'!J62 -> 0
A30: ='На неделю'!K2 -> 154 | B30: ='На неделю'!L2 -> 155 | C30: ='На неделю'!M2 -> 156 | D30: ='На неделю'!N2 -> 157 | E30: ='На неделю'!O2 -> 158
A31: ='На неделю'!K52 -> 0 | B31: ='На неделю'!L52 -> 0 | C31: ='На неделю'!M52 -> 0 | D31: ='На неделю'!N52 -> 0 | E31: ='На неделю'!O52 -> 0
A32: ='На неделю'!K53 -> Физ. культура (Ст/Ч) | B32: ='На неделю'!L53 -> Биология 32 (11) | C32: ='На неделю'!M53 -> Химия 44 (18) | D32: ='На неделю'!N53 -> Черчение 12(2) | E32: ='На неделю'!O53 -> Бел.литература 35(14)
A33: ='На неделю'!K54 -> Бел.литература 35(14) | B33: ='На неделю'!L54 -> Буевич С.В. | C33: ='На неделю'!M54 -> Федорцова А.Т. | D33: ='На неделю'!N54 -> Цыбульская Е.А. | E33: ='На неделю'!O54 -> Физ. культура (Ст/Ч)
A34: ='На неделю'!K55 -> Пр.инф.2/Ин.в пр.1 31/43 | B34: ='На неделю'!L55 -> Математика 45 (19) | C34: ='На неделю'!M55 -> Черчение 12(2) | D34: ='На неделю'!N55 -> Рус.язык 34 (13) | E34: ='На неделю'!O55 -> Бел.язык 35(14)
A35: ='На неделю'!K56 -> Ануфриева/Степанова | B35: ='На неделю'!L56 -> Гончарова Ю.А. | C35: ='На неделю'!M56 -> Цыбульская Е.А. | D35: ='На неделю'!N56 -> Исакова Н.К. | E35: ='На неделю'!O56 -> Черненкова И.А.
A36: ='На неделю'!K57 -> География 32 (11) | B36: ='На неделю'!L57 -> Черчение 12(2) | C36: ='На неделю'!M57 -> Математика 45 (19) | D36: ='На неделю'!N57 -> История Беларуси 21(5) | E36: ='На неделю'!O57 -> Физика 11 (1)
A37: ='На неделю'!K58 -> Буевич С.В. | B37: ='На неделю'!L58 -> Цыбульская Е.А. | C37: ='На неделю'!M58 -> Гончарова Ю.А. | D37: ='На неделю'!N58 -> Сушинская Н.В. | E37: ='На неделю'!O58 -> Гаврилкина Л.П.
A38: ='На неделю'!K59 -> -------------------------------- | B38: ='На неделю'!L59 -> -------------------------------- | C38: ='На неделю'!M59 -> -------------------------------- | D38: ='На неделю'!N59 -> -------------------------------- | E38: ='На неделю'!O59 -> --------------------------------
A39: ='На неделю'!K60 -> -------------------------------- | B39: ='На неделю'!L60 -> -------------------------------- | C39: ='На неделю'!M60 -> -------------------------------- | D39: ='На неделю'!N60 -> -------------------------------- | E39: ='На неделю'!O60 -> --------------------------------
A40: ='На неделю'!K61 -> 0 | B40: ='На неделю'!L61 -> 0 | C40: ='На неделю'!M61 -> 0 | D40: ='На неделю'!N61 -> 0 | E40: ='На неделю'!O61 -> 0
A41: ='На неделю'!K62 -> 0 | B41: ='На неделю'!L62 -> 0 | C41: ='На неделю'!M62 -> 0 | D41: ='На неделю'!N62 -> 0 | E41: ='На неделю'!O62 -> 0
A43: ='На неделю'!P2 -> 159 | B43: ='На неделю'!Q2 -> 160 | C43: ='На неделю'!R2 -> 161 | D43: РАСПИСАНИЕ ЗВОНКОВ
...

Sheet Суббота
A1: Расписание занятий
A2: Суббота
